<?xml version="1.0" encoding="utf-8"?>

<robot name="bipedv5" xmlns:xacro="http://www.ros.org/wiki/xacro">


  <link
    name="base_link">
    <inertial>
      <origin
        xyz="2.1238E-08 2.3955E-08 -0.088578"
        rpy="0 0 0" />
      <mass
        value="6.04" />
      <inertia
        ixx="0.011504"
        ixy="1.2206E-11"
        ixz="4.4303E-12"
        iyy="0.026033"
        iyz="-8.6187E-14"
        izz="0.028285" />
    </inertial>
    <visual>
      <!-- <origin rpy="0 0 0" xyz="0.0 0.0 -0.08"/>
        <geometry>
            <box size="0.35 0.15 0.15"/>
        </geometry> -->
      <origin
        xyz="0 0 0"
        rpy="0 0 0" />
      <geometry>
        <mesh
          filename="package://bipedv5/meshes/base_link.STL" />
      </geometry>
      <material
        name="">
        <color
          rgba="0.89804 0.91765 0.92941 1" />
      </material>
    </visual>
    <collision>
     <origin rpy="0 0 0" xyz="0.0 0.0 -0.08"/>
      <geometry>
          <box size="0.35 0.15 0.15"/>
      </geometry>
    </collision>
  </link>
  <link
    name="left_yaw_Link">
    <inertial>
      <origin
        xyz="-0.0022679 -6.4337E-09 -0.043526"
        rpy="0 0 0" />
      <mass
        value="1.2202" />
      <inertia
        ixx="0.0010452"
        ixy="-7.8902E-18"
        ixz="3.289E-05"
        iyy="0.0011182"
        iyz="-2.6039E-18"
        izz="0.0010959" />
    </inertial>
    <visual>
      <origin
        xyz="0 0 0"
        rpy="0 0 0" />
      <geometry>
        <mesh
          filename="package://bipedv5/meshes/left_yaw_Link.STL" />
      </geometry>
      <material
        name="">
        <color
          rgba="0.89804 0.91765 0.92941 1" />
      </material>
      <!-- <origin rpy="0 0 0" xyz="0 0 -0.007"/>
      <geometry>
          <box size="0.1 0.08 0.03"/>
      </geometry> -->
    </visual>
    <collision>
       <origin rpy="0 0 0" xyz="0 0 -0.007"/>
      <geometry>
          <box size="0.1 0.08 0.03"/>
      </geometry>
    </collision>
  </link>
  <joint
    name="ly"
    type="revolute">
    <origin
      xyz="-0.10249983089623 0 -0.161999985662556"
      rpy="0 0 0" />
    <parent
      link="base_link" />
    <child
      link="left_yaw_Link" />
    <axis
      xyz="0 0 1" />
    <limit
      lower="-10"
      upper="10"
      effort="100"
      velocity="100" />
  </joint>
  <link
    name="left_hip_Link">
    <inertial>
      <origin
        xyz="0.055101 -0.022328 -0.14329"
        rpy="0 0 0" />
      <mass
        value="1.9263" />
      <inertia
        ixx="0.0027475"
        ixy="1.6208E-11"
        ixz="-2.5502E-05"
        iyy="0.0033682"
        iyz="8.3025E-07"
        izz="0.0013004" />
    </inertial>
    <visual>
       <!-- <origin rpy="0 0 0" xyz="0.055 0 -0.076"/>
        <geometry>
            <box size="0.12 0.06 0.206"/>
        </geometry> -->
      <origin
        xyz="0 0 0"
        rpy="0 0 0" />
      <geometry>
        <mesh
          filename="package://bipedv5/meshes/left_hip_Link.STL" />
      </geometry>
      <material
        name="">
        <color
          rgba="0.89804 0.91765 0.92941 1" />
      </material>
    </visual>
    <collision>
      <origin rpy="0 0 0" xyz="0.055 0 -0.076"/>
        <geometry>
            <box size="0.12 0.06 0.206"/>
        </geometry>
    </collision>
  </link>
  <joint
    name="lh"
    type="revolute">
    <origin
      xyz="-0.0565000055020701 0 -0.0539999662335701"
      rpy="0 0 0" />
    <parent
      link="left_yaw_Link" />
    <child
      link="left_hip_Link" />
    <axis
      xyz="-1 0 0" />
    <limit
      lower="-10"
      upper="10"
      effort="100"
      velocity="100" />
  </joint>
  <link
    name="left_knee_pri_Link">
    <inertial>
      <origin
        xyz="-0.003862 2.3753E-10 -0.070547"
        rpy="0 0 0" />
      <mass
        value="1.7288" />
      <inertia
        ixx="0.0013015"
        ixy="9.6218E-19"
        ixz="4.5849E-05"
        iyy="0.0013518"
        iyz="-1.1668E-18"
        izz="0.0012686" />
    </inertial>
    <visual>
      <origin
        xyz="0 0 0"
        rpy="0 0 0" />
      <geometry>
        <mesh
          filename="package://bipedv5/meshes/left_knee_pri_Link.STL" />
      </geometry>
      <material
        name="">
        <color
          rgba="0.89804 0.91765 0.92941 1" />
      </material>
        <!-- <origin rpy="0 0 0" xyz="0.0 0 -0.01"/>
        <geometry>
            <box size="0.14 0.06 0.04"/>
        </geometry> -->
    </visual>
    <collision>
      <origin rpy="0 0 0" xyz="0.0 0 -0.01"/>
        <geometry>
            <box size="0.14 0.06 0.04"/>
        </geometry>
    </collision>
  </link>
  <joint
    name="lkp"
    type="prismatic">
    <origin
      xyz="0.0564999588174406 0 -0.192000034377183"
      rpy="0 0 0" />
    <parent
      link="left_hip_Link" />
    <child
      link="left_knee_pri_Link" />
    <axis
      xyz="1 0 0" />
    <limit
      lower="-0.1"
      upper="0.1"
      effort="100"
      velocity="100" />
  </joint>
  <link
    name="left_knee_Link">
    <inertial>
      <origin
        xyz="0.055101 -0.022328 -0.14329"
        rpy="0 0 0" />
      <mass
        value="1.9263" />
      <inertia
        ixx="0.0027475"
        ixy="1.6208E-11"
        ixz="-2.5502E-05"
        iyy="0.0033682"
        iyz="8.3025E-07"
        izz="0.0013004" />
    </inertial>
    <visual>
      <origin
        xyz="0 0 0"
        rpy="0 0 0" />
      <geometry>
        <mesh
          filename="package://bipedv5/meshes/left_knee_Link.STL" />
      </geometry>
      <material
        name="">
        <color
          rgba="0.89804 0.91765 0.92941 1" />
      </material>
      <!-- <origin rpy="0 0 0" xyz="0.055 0 -0.065"/>
        <geometry>
            <box size="0.12 0.06 0.23"/>
        </geometry> -->
    </visual>
    <collision>
      <origin rpy="0 0 0" xyz="0.055 0 -0.065"/>
        <geometry>
            <box size="0.12 0.06 0.23"/>
        </geometry>
    </collision>
  </link>
  <joint
    name="lk"
    type="revolute">
    <origin
      xyz="-0.0564999588174406 0 -0.082999965622817"
      rpy="0 0 0" />
    <parent
      link="left_knee_pri_Link" />
    <child
      link="left_knee_Link" />
    <axis
      xyz="1 0 0" />
    <limit
      lower="-10"
      upper="10"
      effort="100"
      velocity="100" />
  </joint>
  <link
    name="left_ankle_pri_Link">
    <inertial>
      <origin
        xyz="-0.003862 2.3753E-10 -0.070547"
        rpy="0 0 0" />
      <mass
        value="1.7288" />
      <inertia
        ixx="0.0013015"
        ixy="-5.5659E-19"
        ixz="4.5849E-05"
        iyy="0.0013518"
        iyz="1.5099E-18"
        izz="0.0012686" />
    </inertial>
    <visual>
      <origin
        xyz="0 0 0"
        rpy="0 0 0" />
      <geometry>
        <mesh
          filename="package://bipedv5/meshes/left_ankle_pri_Link.STL" />
      </geometry>
      <material
        name="">
        <color
          rgba="0.89804 0.91765 0.92941 1" />
      </material>
        <!-- <origin rpy="0 0 0" xyz="0.0 0 -0.06"/>
        <geometry>
            <box size="0.14 0.06 0.14"/>
        </geometry> -->
    </visual>
    <collision>
      <origin rpy="0 0 0" xyz="0.0 0 -0.06"/>
        <geometry>
            <box size="0.14 0.06 0.14"/>
        </geometry>
    </collision>
  </link>
  <joint
    name="lap"
    type="prismatic">
    <origin
      xyz="0.0564999588174406 0 -0.192000034377183"
      rpy="0 0 0" />
    <parent
      link="left_knee_Link" />
    <child
      link="left_ankle_pri_Link" />
    <axis
      xyz="1 0 0" />
    <limit
      lower="-0.1"
      upper="0.1"
      effort="100"
      velocity="100" />
  </joint>
  <link
    name="left_ankle_Link">
    <inertial>
      <origin
        xyz="0.054123 0.015256 -0.051677"
        rpy="0 0 0" />
      <mass
        value="0.72668" />
      <inertia
        ixx="0.0020048"
        ixy="-2.246E-18"
        ixz="-7.9275E-07"
        iyy="0.00089396"
        iyz="-9.1373E-07"
        izz="0.0027066" />
    </inertial>
    <visual>
      <origin
        xyz="0 0 0"
        rpy="0 0 0" />
      <geometry>
        <mesh
          filename="package://bipedv5/meshes/left_ankle_Link.STL" />
      </geometry>
      <material
        name="">
        <color
          rgba="0.89804 0.91765 0.92941 1" />
      </material>
      <!-- <origin rpy="0 0 0" xyz="0.055 0.02 -0.06"/>
        <geometry>
            <box size="0.14 0.22 0.01"/>
        </geometry> -->
    </visual>
    <collision>
     <origin rpy="0 0 0" xyz="0.055 0.02 -0.06"/>
        <geometry>
            <box size="0.14 0.22 0.01"/>
        </geometry>
    </collision>
  </link>
  <joint
    name="la"
    type="revolute">
    <origin
      xyz="-0.0565000033098504 0 -0.0830000104027589"
      rpy="0 0 0" />
    <parent
      link="left_ankle_pri_Link" />
    <child
      link="left_ankle_Link" />
    <axis
      xyz="1 0 0" />
    <limit
      lower="-10"
      upper="10"
      effort="100"
      velocity="100" />
  </joint>

  <link
    name="right_yaw_Link">
    <inertial>
      <origin
        xyz="0.0022679 -6.4337E-09 -0.043526"
        rpy="0 0 0" />
      <mass
        value="1.2202" />
      <inertia
        ixx="0.0010452"
        ixy="-2.0231E-18"
        ixz="-3.289E-05"
        iyy="0.0011182"
        iyz="6.9424E-19"
        izz="0.0010959" />
    </inertial>
    <visual>
     <!-- <origin rpy="0 0 0" xyz="0 0 -0.007"/>
      <geometry>
          <box size="0.1 0.08 0.03"/>
      </geometry> -->
      <origin
        xyz="0 0 0"
        rpy="0 0 0" />
      <geometry>
        <mesh
          filename="package://bipedv5/meshes/right_yaw_Link.STL" />
      </geometry>
      <material
        name="">
        <color
          rgba="0.89804 0.91765 0.92941 1" />
      </material>
    </visual>
    <collision>
     <origin rpy="0 0 0" xyz="0 0 -0.007"/>
      <geometry>
          <box size="0.1 0.08 0.03"/>
      </geometry>
    </collision>
  </link>
  <joint
    name="ry"
    type="revolute">
    <origin
      xyz="0.10249993812728 0 -0.161999985662556"
      rpy="0 0 0" />
    <parent
      link="base_link" />
    <child
      link="right_yaw_Link" />
    <axis
      xyz="0 0 -1" />
    <limit
      lower="-10"
      upper="10"
      effort="100"
      velocity="100" />
  </joint>
  <link
    name="right_hip_Link">
    <inertial>
      <origin
        xyz="-0.055101 -0.022328 -0.14329"
        rpy="0 0 0" />
      <mass
        value="1.9263" />
      <inertia
        ixx="0.0027475"
        ixy="1.9779E-11"
        ixz="2.5502E-05"
        iyy="0.0033682"
        iyz="8.3026E-07"
        izz="0.0013004" />
    </inertial>
    <visual>
      <origin
        xyz="0 0 0"
        rpy="0 0 0" />
      <geometry>
        <mesh
          filename="package://bipedv5/meshes/right_hip_Link.STL" />
      </geometry>
      <material
        name="">
        <color
          rgba="0.89804 0.91765 0.92941 1" />
      </material>
      <!-- <origin rpy="0 0 0" xyz="-0.055 0 -0.078"/>
        <geometry>
            <box size="0.12 0.06 0.21"/>
        </geometry> -->
    </visual>
    <collision>
      <origin rpy="0 0 0" xyz="-0.055 0 -0.078"/>
        <geometry>
            <box size="0.12 0.06 0.21"/>
        </geometry>
    </collision>
  </link>
  <joint
    name="rh"
    type="revolute">
    <origin
      xyz="0.0565000055020701 0 -0.0539999662335701"
      rpy="0 0 0" />
    <parent
      link="right_yaw_Link" />
    <child
      link="right_hip_Link" />
    <axis
      xyz="-1 0 0" />
    <limit
      lower="-10"
      upper="10"
      effort="100"
      velocity="100" />
  </joint>
  <link
    name="right_knee_pri_Link">
    <inertial>
      <origin
        xyz="0.003862 2.3753E-10 -0.070547"
        rpy="0 0 0" />
      <mass
        value="1.7288" />
      <inertia
        ixx="0.0013015"
        ixy="6.3708E-19"
        ixz="-4.5849E-05"
        iyy="0.0013518"
        iyz="2.0769E-18"
        izz="0.0012686" />
    </inertial>
    <visual>
      <origin
        xyz="0 0 0"
        rpy="0 0 0" />
      <geometry>
        <mesh
          filename="package://bipedv5/meshes/right_knee_pri_Link.STL" />
      </geometry>
      <material
        name="">
        <color
          rgba="0.89804 0.91765 0.92941 1" />
      </material>
      <!-- <origin rpy="0 0 0" xyz="0.0 0 -0.043"/>
        <geometry>
            <box size="0.14 0.06 0.1"/>
        </geometry> -->
    </visual>
    <collision>
     <origin rpy="0 0 0" xyz="0.0 0 -0.043"/>
        <geometry>
            <box size="0.14 0.06 0.1"/>
        </geometry>
    </collision>
  </link>
  <joint
    name="rkp"
    type="prismatic">
    <origin
      xyz="-0.0565 0 -0.192"
      rpy="0 0 0" />
    <parent
      link="right_hip_Link" />
    <child
      link="right_knee_pri_Link" />
    <axis
      xyz="1 0 0" />
    <limit
      lower="-0.1"
      upper="0.1"
      effort="100"
      velocity="100" />
  </joint>
  <link
    name="right_knee_Link">
    <inertial>
      <origin
        xyz="-0.055101 -0.022328 -0.14329"
        rpy="0 0 0" />
      <mass
        value="1.9263" />
      <inertia
        ixx="0.0027475"
        ixy="1.9779E-11"
        ixz="2.5502E-05"
        iyy="0.0033682"
        iyz="8.3026E-07"
        izz="0.0013004" />
    </inertial>
    <visual>
      <origin
        xyz="0 0 0"
        rpy="0 0 0" />
      <geometry>
        <mesh
          filename="package://bipedv5/meshes/right_knee_Link.STL" />
      </geometry>
      <material
        name="">
        <color
          rgba="0.89804 0.91765 0.92941 1" />
      </material>
       <!-- <origin rpy="0 0 0" xyz="-0.055 0 -0.097"/>
        <geometry>
            <box size="0.12 0.06 0.17"/>
        </geometry> -->
    </visual>
    <collision>
      <origin rpy="0 0 0" xyz="-0.055 0 -0.097"/>
        <geometry>
            <box size="0.12 0.06 0.17"/>
        </geometry>
    </collision>
  </link>
  <joint
    name="rk"
    type="revolute">
    <origin
      xyz="0.0564999588174397 0 -0.0829999656228171"
      rpy="0 0 0" />
    <parent
      link="right_knee_pri_Link" />
    <child
      link="right_knee_Link" />
    <axis
      xyz="1 0 0" />
    <limit
      lower="-10"
      upper="10"
      effort="100"
      velocity="100" />
  </joint>
  <link
    name="right_ankle_pri_Link">
    <inertial>
      <origin
        xyz="0.003862 2.3753E-10 -0.070547"
        rpy="0 0 0" />
      <mass
        value="1.7288" />
      <inertia
        ixx="0.0013015"
        ixy="5.2116E-19"
        ixz="-4.5849E-05"
        iyy="0.0013518"
        iyz="2.0394E-18"
        izz="0.0012686" />
    </inertial>
    <visual>
      <origin
        xyz="0 0 0"
        rpy="0 0 0" />
      <geometry>
        <mesh
          filename="package://bipedv5/meshes/right_ankle_pri_Link.STL" />
      </geometry>
      <material
        name="">
        <color
          rgba="0.89804 0.91765 0.92941 1" />
      </material>
       <!-- <origin rpy="0 0 0" xyz="0.0 0 -0.06"/>
        <geometry>
            <box size="0.14 0.06 0.14"/>
        </geometry> -->
    </visual>
    <collision>
     <origin rpy="0 0 0" xyz="0.0 0 -0.06"/>
        <geometry>
            <box size="0.14 0.06 0.14"/>
        </geometry>
    </collision>
  </link>
  <joint
    name="rap"
    type="prismatic">
    <origin
      xyz="-0.0564999588174397 0 -0.192000034377183"
      rpy="0 0 0" />
    <parent
      link="right_knee_Link" />
    <child
      link="right_ankle_pri_Link" />
    <axis
      xyz="1 0 0" />
    <limit
      lower="-0.1"
      upper="0.1"
      effort="100"
      velocity="100" />
  </joint>
  <link
    name="right_ankle_Link">
    <inertial>
      <origin
        xyz="-0.054123 0.015256 -0.051677"
        rpy="0 0 0" />
      <mass
        value="0.72668" />
      <inertia
        ixx="0.0020048"
        ixy="1.7327E-17"
        ixz="7.9275E-07"
        iyy="0.00089396"
        iyz="-9.1373E-07"
        izz="0.0027066" />
    </inertial>
    <visual>
       <!-- <origin rpy="0 0 0" xyz="-0.055 0.02 -0.06"/>
        <geometry>
            <box size="0.14 0.22 0.01"/>
        </geometry> -->
      <origin
        xyz="0 0 0"
        rpy="0 0 0" />
      <geometry>
        <mesh
          filename="package://bipedv5/meshes/right_ankle_Link.STL" />
      </geometry>
      <material
        name="">
        <color
          rgba="0.89804 0.91765 0.92941 1" />
      </material>
    </visual>
    <collision>
      <origin rpy="0 0 0" xyz="-0.055 0.02 -0.06"/>
        <geometry>
            <box size="0.14 0.22 0.01"/>
        </geometry>
    </collision>
  </link>
  <joint
    name="ra"
    type="revolute">
    <origin
      xyz="0.0565000033098499 0 -0.083000010402759"
      rpy="0 0 0" />
    <parent
      link="right_ankle_pri_Link" />
    <child
      link="right_ankle_Link" />
    <axis
      xyz="1 0 0" />
    <limit
      lower="-10"
      upper="10"
      effort="100"
      velocity="100" />
  </joint>



</robot>
